Workbook

Sheet README
A1: EverVerse — guide recruitment through faith organisations
A2: Nine starter countries · built 13 September 2026 from RECRUIT.txt · one-pager: eververse.org/partners.html
A4: How to use this workbook
A5: 1. Organisations — the working list. Yellow cells are yours to fill: Website, Contact email, Source URL, Approved, Status, dates, Outcome, Notes. Everything else was pre-filled and can be edited too.
A6: 2. Find each contact address on the organisation's OFFICIAL website the day you write, and paste the page you found it on into Source URL. Do not scrape or buy lists. Addresses go stale; a guessed one bounces or lands with the wrong person.
A7: 3. Set Approved = Y once the name and address are confirmed. Nothing is sent to a row that is not approved.
A8: 4. When you send, put the date in Sent. Follow-up due fills itself (+10 days). One follow-up, then stop. Log the reply date and a one-word Outcome — never paste a reply's contents.
A9: 5. Dashboard counts everything by country and by ask. Countries shows what each starter still needs (from regions.js on the build date).
A10: 6. Templates holds the emails. Send from team@eververse.org, signed 'EverVerse Team'. Spanish, Portuguese and Indonesian are DRAFTS — a native speaker reads them before the first send.
A12: Legend
A13: Yellow fill = a cell for you to fill in. Blue text = a value you can change (dropdown or date). Black = pre-filled or a formula.
A14: Fit codes: G = can send guides · L = can verify the crisis helpline · N = native speaker to review crisis patterns · C = can confirm a guide's affiliation when we ring.
... A50: above 1 and stays there.

Sheet Dashboard
A1: Recruitment dashboard
A2: All numbers are formulas over the Organisations sheet. Update that sheet; this one follows.
A4: Measure | B4: Value
A5: Organisations listed | B5: =COUNTA(Organisations!$D$3:$D$97) -> 95
A6: Address found | B6: =COUNTIF(Organisations!$I$3:$I$97,"?*") -> 0
A7: Approved | B7: =COUNTIF(Organisations!$K$3:$K$97,"Y") -> 0
A8: Sent | B8: =COUNTIF(Organisations!$M$3:$M$97,"<>") -> 0
A9: Follow-ups due (sent ≥10 days ago, no reply) | B9: =SUMPRODUCT((Organisations!$M$3:$M$97<>"")*(Organisations!$M$3:$M$97<=TODAY()-10)*(Organisations!$O$3:$O$97="")) -> 0
A10: Replied | B10: =COUNTIF(Organisations!$O$3:$O$97,"<>") -> 0
A11: Reply rate | B11: =IF(COUNTIF(Organisations!$M$3:$M$97,"<>")=0,0,COUNTIF(Organisations!$O$3:$O$97,"<>")/COUNTIF(Organisations!$M$3:$M$97,"<>")) -> 0
A12: Declined / bounced | B12: =COUNTIF(Organisations!$L$3:$L$97,"declined")+COUNTIF(Organisations!$L$3:$L$97,"bounced") -> 0
A15: Country | B15: Listed | C15: Approved | D15: Sent | E15: Replied | F15: Can verify line | G15: Native reviewers
A16: United States | B16: =COUNTIF(Organisations!$C$3:$C$97,"US") -> 13 | C16: =COUNTIFS(Organisations!$C$3:$C$97,"US",Organisations!$K$3:$K$97,"Y") -> 0 | D16: =COUNTIFS(Organisations!$C$3:$C$97,"US",Organisations!$M$3:$M$97,"<>") -> 0 | E16: =COUNTIFS(Organisations!$C$3:$C$97,"US",Organisations!$O$3:$O$97,"<>") -> 0 | F16: =SUMPRODUCT((Organisations!$C$3:$C$97="US")*ISNUMBER(SEARCH("L",Organisations!$F$3:$F$97))) -> 1 | G16: =SUMPRODUCT((Organisations!$C$3:$C$97="US")*ISNUMBER(SEARCH("N",Organisations!$F$3:$F$97))) -> 2
A17: Brazil | B17: =COUNTIF(Organisations!$C$3:$C$97,"BR") -> 9 | C17: =COUNTIFS(Organisations!$C$3:$C$97,"BR",Organisations!$K$3:$K$97,"Y") -> 0 | D17: =COUNTIFS(Organisations!$C$3:$C$97,"BR",Organisations!$M$3:$M$97,"<>") -> 0 | E17: =COUNTIFS(Organisations!$C$3:$C$97,"BR",Organisations!$O$3:$O$97,"<>") -> 0 | F17: =SUMPRODUCT((Organisations!$C$3:$C$97="BR")*ISNUMBER(SEARCH("L",Organisations!$F$3:$F$97))) -> 1 | G17: =SUMPRODUCT((Organisations!$C$3:$C$97="BR")*ISNUMBER(SEARCH("N",Organisations!$F$3:$F$97))) -> 1
A18: Mexico | B18: =COUNTIF(Organisations!$C$3:$C$97,"MX") -> 8 | C18: =COUNTIFS(Organisations!$C$3:$C$97,"MX",Organisations!$K$3:$K$97,"Y") -> 0 | D18: =COUNTIFS(Organisations!$C$3:$C$97,"MX",Organisations!$M$3:$M$97,"<>") -> 0 | E18: =COUNTIFS(Organisations!$C$3:$C$97,"MX",Organisations!$O$3:$O$97,"<>") -> 0 | F18: =SUMPRODUCT((Organisations!$C$3:$C$97="MX")*ISNUMBER(SEARCH("L",Organisations!$F$3:$F$97))) -> 1 | G18: =SUMPRODUCT((Organisations!$C$3:$C$97="MX")*ISNUMBER(SEARCH("N",Organisations!$F$3:$F$97))) -> 1
A19: India | B19: =COUNTIF(Organisations!$C$3:$C$97,"IN") -> 15 | C19: =COUNTIFS(Organisations!$C$3:$C$97,"IN",Organisations!$K$3:$K$97,"Y") -> 0 | D19: =COUNTIFS(Organisations!$C$3:$C$97,"IN",Organisations!$M$3:$M$97,"<>") -> 0 | E19: =COUNTIFS(Organisations!$C$3:$C$97,"IN",Organisations!$O$3:$O$97,"<>") -> 0 | F19: =SUMPRODUCT((Organisations!$C$3:$C$97="IN")*ISNUMBER(SEARCH("L",Organisations!$F$3:$F$97))) -> 2 | G19: =SUMPRODUCT((Organisations!$C$3:$C$97="IN")*ISNUMBER(SEARCH("N",Organisations!$F$3:$F$97))) -> 2
A20: Philippines | B20: =COUNTIF(Organisations!$C$3:$C$97,"PH") -> 8 | C20: =COUNTIFS(Organisations!$C$3:$C$97,"PH",Organisations!$K$3:$K$97,"Y") -> 0 | D20: =COUNTIFS(Organisations!$C$3:$C$97,"PH",Organisations!$M$3:$M$97,"<>") -> 0 | E20: =COUNTIFS(Organisations!$C$3:$C$97,"PH",Organisations!$O$3:$O$97,"<>") -> 0 | F20: =SUMPRODUCT((Organisations!$C$3:$C$97="PH")*ISNUMBER(SEARCH("L",Organisations!$F$3:$F$97))) -> 3 | G20: =SUMPRODUCT((Organisations!$C$3:$C$97="PH")*ISNUMBER(SEARCH("N",Organisations!$F$3:$F$97))) -> 1
A21: Indonesia | B21: =COUNTIF(Organisations!$C$3:$C$97,"ID") -> 8 | C21: =COUNTIFS(Organisations!$C$3:$C$97,"ID",Organisations!$K$3:$K$97,"Y") -> 0 | D21: =COUNTIFS(Organisations!$C$3:$C$97,"ID",Organisations!$M$3:$M$97,"<>") -> 0 | E21: =COUNTIFS(Organisations!$C$3:$C$97,"ID",Organisations!$O$3:$O$97,"<>") -> 0 | F21: =SUMPRODUCT((Organisations!$C$3:$C$97="ID")*ISNUMBER(SEARCH("L",Organisations!$F$3:$F$97))) -> 1 | G21: =SUMPRODUCT((Organisations!$C$3:$C$97="ID")*ISNUMBER(SEARCH("N",Organisations!$F$3:$F$97))) -> 2
A22: Nigeria | B22: =COUNTIF(Organisations!$C$3:$C$97,"NG") -> 12 | C22: =COUNTIFS(Organisations!$C$3:$C$97,"NG",Organisations!$K$3:$K$97,"Y") -> 0 | D22: =COUNTIFS(Organisations!$C$3:$C$97,"NG",Organisations!$M$3:$M$97,"<>") -> 0 | E22: =COUNTIFS(Organisations!$C$3:$C$97,"NG",Organisations!$O$3:$O$97,"<>") -> 0 | F22: =SUMPRODUCT((Organisations!$C$3:$C$97="NG")*ISNUMBER(SEARCH("L",Organisations!$F$3:$F$97))) -> 2 | G22: =SUMPRODUCT((Organisations!$C$3:$C$97="NG")*ISNUMBER(SEARCH("N",Organisations!$F$3:$F$97))) -> 3
A23: Kenya | B23: =COUNTIF(Organisations!$C$3:$C$97,"KE") -> 10 | C23: =COUNTIFS(Organisations!$C$3:$C$97,"KE",Organisations!$K$3:$K$97,"Y") -> 0 | D23: =COUNTIFS(Organisations!$C$3:$C$97,"KE",Organisations!$M$3:$M$97,"<>") -> 0 | E23: =COUNTIFS(Organisations!$C$3:$C$97,"KE",Organisations!$O$3:$O$97,"<>") -> 0 | F23: =SUMPRODUCT((Organisations!$C$3:$C$97="KE")*ISNUMBER(SEARCH("L",Organisations!$F$3:$F$97))) -> 2 | G23: =SUMPRODUCT((Organisations!$C$3:$C$97="KE")*ISNUMBER(SEARCH("N",Organisations!$F$3:$F$97))) -> 1
A24: South Africa | B24: =COUNTIF(Organisations!$C$3:$C$97,"ZA") -> 12 | C24: =COUNTIFS(Organisations!$C$3:$C$97,"ZA",Organisations!$K$3:$K$97,"Y") -> 0 | D24: =COUNTIFS(Organisations!$C$3:$C$97,"ZA",Organisations!$M$3:$M$97,"<>") -> 0 | E24: =COUNTIFS(Organisations!$C$3:$C$97,"ZA",Organisations!$O$3:$O$97,"<>") -> 0 | F24: =SUMPRODUCT((Organisations!$C$3:$C$97="ZA")*ISNUMBER(SEARCH("L",Organisations!$F$3:$F$97))) -> 2 | G24: =SUMPRODUCT((Organisations!$C$3:$C$97="ZA")*ISNUMBER(SEARCH("N",Organisations!$F$3:$F$97))) -> 1
A25: Total | B25: =SUM(B16:B24) -> 95 | C25: =SUM(C16:C24) -> 0 | D25: =SUM(D16:D24) -> 0 | E25: =SUM(E16:E24) -> 0 | F25: =SUM(F16:F24) -> 15 | G25: =SUM(G16:G24) -> 14
A28: By ask | B28: Organisations that fit
A29: G — can send guides | B29: =SUMPRODUCT(ISNUMBER(SEARCH("G",Organisations!$F$3:$F$97))*1) -> 84
A30: L — can verify the crisis line | B30: =SUMPRODUCT(ISNUMBER(SEARCH("L",Organisations!$F$3:$F$97))*1) -> 15
A31: N — native speaker for pattern review | B31: =SUMPRODUCT(ISNUMBER(SEARCH("N",Organisations!$F$3:$F$97))*1) -> 14
A32: C — can confirm affiliations | B32: =SUMPRODUCT(ISNUMBER(SEARCH("C",Organisations!$F$3:$F$97))*1) -> 62

Sheet Organisations
A1: # | B1: Country | C1: CC | D1: Organisation | E1: Faith | F1: Fit (G/L/N/C) | G1: Why / note | H1: Website | I1: Contact email | J1: Source URL (page the address came from) | K1: Approved (Y/N) | L1: Status | M1: Sent (date) | N1: Follow-up due | O1: Replied (date) | P1: Outcome | Q1: Notes
A2: ex. | B2: United States | C2: US | D2: EXAMPLE — Stephen Ministries (delete this row) | E2: Christian | F2: G, C | G2: example row showing the expected format | H2: https://www.stephenministries.org | I2: info@example.org | J2: https://www.stephenministries.org/contact | K2: Y | L2: sent | M2: =DATE(2026,9,15) -> 46280 | N2: =IF(M2="","",M2+10) -> 46290 | Q2: example only
A3: 1 | B3: United States | C3: US | D3: Stephen Ministries | E3: Christian | F3: G, C | G3: lay caring ministry — the single closest thing to a guide that already exists; 600k trained | K3: N | L3: new | N3: =IF(M3="","",M3+10)
A4: 2 | B4: United States | C4: US | D4: Catholic Charities USA / diocesan offices | E4: Christian | F4: G, C | K4: N | L4: new | N4: =IF(M4="","",M4+10)
A5: 3 | B5: United States | C5: US | D5: National Council of Churches USA | E5: Christian | F5: G | G5: forwards to 37 denominations | K5: N | L5: new | N5: =IF(M5="","",M5+10)
A6: 4 | B6: United States | C6: US | D6: Association of Professional Chaplains | E6: All | F6: G, N | G6: chaplains want service records | K6: N | L6: new | N6: =IF(M6="","",M6+10)
A7: 5 | B7: United States | C7: US | D7: ACPE (clinical pastoral education) | E7: All | F7: G | G7: CPE students need hours; the letter of service is the pitch | K7: N | L7: new | N7: =IF(M7="","",M7+10)
A8: 6 | B8: United States | C8: US | D8: Islamic Society of North America (ISNA) | E8: Islam | F8: G, C | K8: N | L8: new | N8: =IF(M8="","",M8+10)
A9: 7 | B9: United States | C9: US | D9: Hindu American Foundation | E9: Hindu | F9: G | K9: N | L9: new | N9: =IF(M9="","",M9+10)
A10: 8 | B10: United States | C10: US | D10: BAPS Swaminarayan Sanstha (US temples) | E10: Hindu | F10: G, C | G10: strong volunteer culture, Gujarati | K10: N | L10: new | N10: =IF(M10="","",M10+10)
A11: 9 | B11: United States | C11: US | D11: Sikh Coalition / United Sikhs | E11: Sikh | F11: G, C | G11: Punjabi | K11: N | L11: new | N11: =IF(M11="","",M11+10)
A12: 10 | B12: United States | C12: US | D12: Jewish Federations of North America / Jewish Family Service | E12: Jewish | F12: G, C | K12: N | L12: new | N12: =IF(M12="","",M12+10)
A13: 11 | B13: United States | C13: US | D13: Buddhist Churches of America | E13: Buddhist | F13: G | K13: N | L13: new | N13: =IF(M13="","",M13+10)
A14: 12 | B14: United States | C14: US | D14: 988 Lifeline (Vibrant Emotional Health) | E14: All | F14: L | G14: verify our US entry | K14: N | L14: new | N14: =IF(M14="","",M14+10)
A15: 13 | B15: United States | C15: US | D15: Spanish-speaking: Hispanic Ministry offices of the USCCB; Hermanas/Assemblies of God Hispanic districts | E15: Christian | F15: G, N (es) | K15: N | L15: new | N15: =IF(M15="","",M15+10)
A16: 14 | B16: Brazil | C16: BR | D16: CNBB — Conferência Nacional dos Bispos do Brasil | E16: Christian | F16: G, C | K16: N | L16: new | N16: =IF(M16="","",M16+10)
A17: 15 | B17: Brazil | C17: BR | D17: Cáritas Brasileira | E17: Christian | F17: G, C | K17: N | L17: new | N17: =IF(M17="","",M17+10)
A18: 16 | B18: Brazil | C18: BR | D18: Pastoral da Saúde / Pastoral da Escuta | E18: Christian | F18: G | G18: already do "listening" ministry in hospitals | K18: N | L18: new | N18: =IF(M18="","",M18+10)
A19: 17 | B19: Brazil | C19: BR | D19: Convenção Geral das Assembleias de Deus (CGADB) | E19: Christian | F19: G, C | K19: N | L19: new | N19: =IF(M19="","",M19+10)
A20: 18 | B20: Brazil | C20: BR | D20: Igreja Presbiteriana do Brasil | E20: Christian | F20: G, C | K20: N | L20: new | N20: =IF(M20="","",M20+10)
A21: 19 | B21: Brazil | C21: BR | D21: CVV — Centro de Valorização da Vida | E21: All | F21: L, G | G21: runs the 188 line; volunteer listeners; verify our entry | K21: N | L21: new | N21: =IF(M21="","",M21+10)
A22: 20 | B22: Brazil | C22: BR | D22: FAMBRAS — Federação das Associações Muçulmanas do Brasil | E22: Islam | F22: G, C | K22: N | L22: new | N22: =IF(M22="","",M22+10)
A23: 21 | B23: Brazil | C23: BR | D23: CONIB — Confederação Israelita do Brasil | E23: Jewish | F23: G, C | K23: N | L23: new | N23: =IF(M23="","",M23+10)
A24: 22 | B24: Brazil | C24: BR | D24: Faculdades de teologia (PUC-Rio, EST São Leopoldo) | E24: Christian | F24: G (students), N (pt) | K24: N | L24: new | N24: =IF(M24="","",M24+10)
A25: 23 | B25: Mexico | C25: MX | D25: CEM — Conferencia del Episcopado Mexicano | E25: Christian | F25: G, C | K25: N | L25: new | N25: =IF(M25="","",M25+10)
A26: 24 | B26: Mexico | C26: MX | D26: Cáritas Mexicana | E26: Christian | F26: G, C | K26: N | L26: new | N26: =IF(M26="","",M26+10)
A27: 25 | B27: Mexico | C27: MX | D27: CONFRATERNICE — Confraternidad Nacional de Iglesias Cristianas Evangélicas | E27: Christian | F27: G, C | K27: N | L27: new | N27: =IF(M27="","",M27+10)
A28: 26 | B28: Mexico | C28: MX | D28: Consejo Interreligioso de México | E28: All | F28: G, C | G28: one door to several faiths | K28: N | L28: new | N28: =IF(M28="","",M28+10)
A29: 27 | B29: Mexico | C29: MX | D29: Comité Central de la Comunidad Judía de México | E29: Jewish | F29: G, C | K29: N | L29: new | N29: =IF(M29="","",M29+10)
A30: 28 | B30: Mexico | C30: MX | D30: Centro Cultural Islámico de México | E30: Islam | F30: G | K30: N | L30: new | N30: =IF(M30="","",M30+10)
A31: 29 | B31: Mexico | C31: MX | D31: SAPTEL | E31: All | F31: L | G31: runs the line we show; verify our entry | K31: N | L31: new | N31: =IF(M31="","",M31+10)
A32: 30 | B32: Mexico | C32: MX | D32: Universidad Pontificia de México / seminarios diocesanos | E32: Christian | F32: G (students), N (es) | K32: N | L32: new | N32: =IF(M32="","",M32+10)
A33: 31 | B33: India | C33: IN | D33: CBCI — Catholic Bishops' Conference of India | E33: Christian | F33: G, C | K33: N | L33: new | N33: =IF(M33="","",M33+10)
A34: 32 | B34: India | C34: IN | D34: Caritas India | E34: Christian | F34: G, C | K34: N | L34: new | N34: =IF(M34="","",M34+10)
A35: 33 | B35: India | C35: IN | D35: National Council of Churches in India | E35: Christian | F35: G, C | K35: N | L35: new | N35: =IF(M35="","",M35+10)
A36: 34 | B36: India | C36: IN | D36: Ramakrishna Mission | E36: Hindu | F36: G, C | G36: service ethic, many languages | K36: N | L36: new | N36: =IF(M36="","",M36+10)
A37: 35 | B37: India | C37: IN | D37: Chinmaya Mission | E37: Hindu | F37: G, C | K37: N | L37: new | N37: =IF(M37="","",M37+10)
A38: 36 | B38: India | C38: IN | D38: ISKCON (India temples) | E38: Hindu | F38: G, C | K38: N | L38: new | N38: =IF(M38="","",M38+10)
A39: 37 | B39: India | C39: IN | D39: The Art of Living | E39: Hindu | F39: G | G39: very large volunteer base | K39: N | L39: new | N39: =IF(M39="","",M39+10)
A40: 38 | B40: India | C40: IN | D40: Ismaili Council for India / AKDN | E40: Islam | F40: G, C | G40: strong volunteer tradition | K40: N | L40: new | N40: =IF(M40="","",M40+10)
...

Sheet Countries
A1: CC | B1: Country | C1: Region | D1: Languages (* = patterns unreviewed) | E1: Crisis line shown | F1: Line name | G1: Line status | H1: Readiness (13 Sep 2026) | I1: Next step | J1: Everything missing | K1: Orgs listed | L1: Approved | M1: Sent | N1: Replied | O1: Can verify line (L) | P1: Native reviewers (N)
A2: US | B2: United States | C2: Americas | D2: en, es* | E2: 988 | F2: Suicide & Crisis Lifeline | G2: unverified | H2: red | I2: crisis line not yet verified by a person in United States | J2: crisis line not yet verified by a person in United States | no active guide writes in en | K2: =COUNTIF(Organisations!$C$3:$C$97,A2) -> 13 | L2: =COUNTIFS(Organisations!$C$3:$C$97,A2,Organisations!$K$3:$K$97,"Y") -> 0 | M2: =COUNTIFS(Organisations!$C$3:$C$97,A2,Organisations!$M$3:$M$97,"<>") -> 0 | N2: =COUNTIFS(Organisations!$C$3:$C$97,A2,Organisations!$O$3:$O$97,"<>") -> 0 | O2: =SUMPRODUCT((Organisations!$C$3:$C$97=A2)*ISNUMBER(SEARCH("L",Organisations!$F$3:$F$97))) -> 1 | P2: =SUMPRODUCT((Organisations!$C$3:$C$97=A2)*ISNUMBER(SEARCH("N",Organisations!$F$3:$F$97))) -> 2
A3: BR | B3: Brazil | C3: Americas | D3: pt* | E3: 188 | F3: CVV — Centro de Valorização da Vida | G3: unverified | H3: red | I3: crisis line not yet verified by a person in Brazil | J3: crisis line not yet verified by a person in Brazil | crisis patterns in pt not yet read by a native speaker | no active guide writes in pt | K3: =COUNTIF(Organisations!$C$3:$C$97,A3) -> 9 | L3: =COUNTIFS(Organisations!$C$3:$C$97,A3,Organisations!$K$3:$K$97,"Y") -> 0 | M3: =COUNTIFS(Organisations!$C$3:$C$97,A3,Organisations!$M$3:$M$97,"<>") -> 0 | N3: =COUNTIFS(Organisations!$C$3:$C$97,A3,Organisations!$O$3:$O$97,"<>") -> 0 | O3: =SUMPRODUCT((Organisations!$C$3:$C$97=A3)*ISNUMBER(SEARCH("L",Organisations!$F$3:$F$97))) -> 1 | P3: =SUMPRODUCT((Organisations!$C$3:$C$97=A3)*ISNUMBER(SEARCH("N",Organisations!$F$3:$F$97))) -> 1
A4: MX | B4: Mexico | C4: Americas | D4: es* | E4: 800 911 2000 | F4: SAPTEL | G4: unverified | H4: red | I4: crisis line not yet verified by a person in Mexico | J4: crisis line not yet verified by a person in Mexico | crisis patterns in es not yet read by a native speaker | no active guide writes in es | K4: =COUNTIF(Organisations!$C$3:$C$97,A4) -> 8 | L4: =COUNTIFS(Organisations!$C$3:$C$97,A4,Organisations!$K$3:$K$97,"Y") -> 0 | M4: =COUNTIFS(Organisations!$C$3:$C$97,A4,Organisations!$M$3:$M$97,"<>") -> 0 | N4: =COUNTIFS(Organisations!$C$3:$C$97,A4,Organisations!$O$3:$O$97,"<>") -> 0 | O4: =SUMPRODUCT((Organisations!$C$3:$C$97=A4)*ISNUMBER(SEARCH("L",Organisations!$F$3:$F$97))) -> 1 | P4: =SUMPRODUCT((Organisations!$C$3:$C$97=A4)*ISNUMBER(SEARCH("N",Organisations!$F$3:$F$97))) -> 1
A5: IN | B5: India | C5: Asia | D5: hi*, en, bn*, te*, mr*, ta*, gu*, ur*, ml*, pa* | E5: 14416 | F5: Tele-MANAS | G5: unverified | H5: red | I5: crisis line not yet verified by a person in India | J5: crisis line not yet verified by a person in India | crisis patterns in hi not yet read by a native speaker | no active guide writes in hi | K5: =COUNTIF(Organisations!$C$3:$C$97,A5) -> 15 | L5: =COUNTIFS(Organisations!$C$3:$C$97,A5,Organisations!$K$3:$K$97,"Y") -> 0 | M5: =COUNTIFS(Organisations!$C$3:$C$97,A5,Organisations!$M$3:$M$97,"<>") -> 0 | N5: =COUNTIFS(Organisations!$C$3:$C$97,A5,Organisations!$O$3:$O$97,"<>") -> 0 | O5: =SUMPRODUCT((Organisations!$C$3:$C$97=A5)*ISNUMBER(SEARCH("L",Organisations!$F$3:$F$97))) -> 2 | P5: =SUMPRODUCT((Organisations!$C$3:$C$97=A5)*ISNUMBER(SEARCH("N",Organisations!$F$3:$F$97))) -> 2
A6: PH | B6: Philippines | C6: Asia | D6: tl*, en | E6: 1553 | F6: NCMH Crisis Hotline | G6: unverified | H6: red | I6: crisis line not yet verified by a person in Philippines | J6: crisis line not yet verified by a person in Philippines | crisis patterns in tl not yet read by a native speaker | no active guide writes in tl | K6: =COUNTIF(Organisations!$C$3:$C$97,A6) -> 8 | L6: =COUNTIFS(Organisations!$C$3:$C$97,A6,Organisations!$K$3:$K$97,"Y") -> 0 | M6: =COUNTIFS(Organisations!$C$3:$C$97,A6,Organisations!$M$3:$M$97,"<>") -> 0 | N6: =COUNTIFS(Organisations!$C$3:$C$97,A6,Organisations!$O$3:$O$97,"<>") -> 0 | O6: =SUMPRODUCT((Organisations!$C$3:$C$97=A6)*ISNUMBER(SEARCH("L",Organisations!$F$3:$F$97))) -> 3 | P6: =SUMPRODUCT((Organisations!$C$3:$C$97=A6)*ISNUMBER(SEARCH("N",Organisations!$F$3:$F$97))) -> 1
A7: ID | B7: Indonesia | C7: Asia | D7: id* | E7: 119 | F7: Kemenkes SEJIWA | G7: unverified | H7: red | I7: crisis line not yet verified by a person in Indonesia | J7: crisis line not yet verified by a person in Indonesia | crisis patterns in id not yet read by a native speaker | no active guide writes in id | K7: =COUNTIF(Organisations!$C$3:$C$97,A7) -> 8 | L7: =COUNTIFS(Organisations!$C$3:$C$97,A7,Organisations!$K$3:$K$97,"Y") -> 0 | M7: =COUNTIFS(Organisations!$C$3:$C$97,A7,Organisations!$M$3:$M$97,"<>") -> 0 | N7: =COUNTIFS(Organisations!$C$3:$C$97,A7,Organisations!$O$3:$O$97,"<>") -> 0 | O7: =SUMPRODUCT((Organisations!$C$3:$C$97=A7)*ISNUMBER(SEARCH("L",Organisations!$F$3:$F$97))) -> 1 | P7: =SUMPRODUCT((Organisations!$C$3:$C$97=A7)*ISNUMBER(SEARCH("N",Organisations!$F$3:$F$97))) -> 2
A8: NG | B8: Nigeria | C8: Africa | D8: en, ha*, yo* | E8: emergency only 112 | G8: emergency-only | H8: red | I8: no crisis line, only an emergency number — find one, then verify it | J8: no crisis line, only an emergency number — find one, then verify it | no active guide writes in en | K8: =COUNTIF(Organisations!$C$3:$C$97,A8) -> 12 | L8: =COUNTIFS(Organisations!$C$3:$C$97,A8,Organisations!$K$3:$K$97,"Y") -> 0 | M8: =COUNTIFS(Organisations!$C$3:$C$97,A8,Organisations!$M$3:$M$97,"<>") -> 0 | N8: =COUNTIFS(Organisations!$C$3:$C$97,A8,Organisations!$O$3:$O$97,"<>") -> 0 | O8: =SUMPRODUCT((Organisations!$C$3:$C$97=A8)*ISNUMBER(SEARCH("L",Organisations!$F$3:$F$97))) -> 2 | P8: =SUMPRODUCT((Organisations!$C$3:$C$97=A8)*ISNUMBER(SEARCH("N",Organisations!$F$3:$F$97))) -> 3
A9: KE | B9: Kenya | C9: Africa | D9: sw*, en | E9: 1199 | F9: Kenya Red Cross mental health line | G9: unverified | H9: red | I9: crisis line not yet verified by a person in Kenya | J9: crisis line not yet verified by a person in Kenya | crisis patterns in sw not yet read by a native speaker | no active guide writes in sw | K9: =COUNTIF(Organisations!$C$3:$C$97,A9) -> 10 | L9: =COUNTIFS(Organisations!$C$3:$C$97,A9,Organisations!$K$3:$K$97,"Y") -> 0 | M9: =COUNTIFS(Organisations!$C$3:$C$97,A9,Organisations!$M$3:$M$97,"<>") -> 0 | N9: =COUNTIFS(Organisations!$C$3:$C$97,A9,Organisations!$O$3:$O$97,"<>") -> 0 | O9: =SUMPRODUCT((Organisations!$C$3:$C$97=A9)*ISNUMBER(SEARCH("L",Organisations!$F$3:$F$97))) -> 2 | P9: =SUMPRODUCT((Organisations!$C$3:$C$97=A9)*ISNUMBER(SEARCH("N",Organisations!$F$3:$F$97))) -> 1
A10: ZA | B10: South Africa | C10: Africa | D10: en, zu* | E10: 0800 567 567 | F10: SADAG | G10: unverified | H10: red | I10: crisis line not yet verified by a person in South Africa | J10: crisis line not yet verified by a person in South Africa | no active guide writes in en | K10: =COUNTIF(Organisations!$C$3:$C$97,A10) -> 12 | L10: =COUNTIFS(Organisations!$C$3:$C$97,A10,Organisations!$K$3:$K$97,"Y") -> 0 | M10: =COUNTIFS(Organisations!$C$3:$C$97,A10,Organisations!$M$3:$M$97,"<>") -> 0 | N10: =COUNTIFS(Organisations!$C$3:$C$97,A10,Organisations!$O$3:$O$97,"<>") -> 0 | O10: =SUMPRODUCT((Organisations!$C$3:$C$97=A10)*ISNUMBER(SEARCH("L",Organisations!$F$3:$F$97))) -> 2 | P10: =SUMPRODUCT((Organisations!$C$3:$C$97=A10)*ISNUMBER(SEARCH("N",Organisations!$F$3:$F$97))) -> 1
A12: Readiness, next step and crisis line are a snapshot from regions.js / world.js on 13 Sep 2026; the live truth is the Regions panel on the Health screen. Green needs: verified line + patterns reviewed + 3 guides in one of its languages.

Sheet Templates
A1: Email templates — send from team@eververse.org, signed EverVerse Team
A2: Fill [placeholders] per organisation. The English email passes checkCampaignCopy() and checkGivingCopy(); if you edit it, run it through both again (campaign.js / giving.js). Translations are drafts until a native speaker has read them.
A4: English — main
A5: THE EMAIL (English) ------------------- From: EverVerse Team <team@eververse.org> Subject: One of your people, one blessing — a volunteer ask from EverVerse Dear [office / name of the ministry or council], Someone in your tradition is going to write, tonight, about the worst thing in their life — a death, an illness, a marriage ending, a faith gone quiet — and hope that a real person writes back. We run the Blessing Circle at eververse.org: a free service where an adult writes anonymously, and a checked volunteer from their own faith writes back once, with a verse from their own scripture and a few honest words of their own. No account, nothing to buy, and no AI writes a single word — we say that on our front door. We are opening it in [country] and we would rather do it with you than around you. Three asks, in order of size: 1. Ten people in your community who have carried something and could each write one blessing. Not clergy necessarily. Ten minutes to apply, and a person reads every application: eververse.org/guides.html 2. One hour from one person who lives in [country]: to check that the crisis helpline we show — [line as in world.js] — is the right one, and to read the phrases we use to recognise crisis in [language]. We will not promote the Circle in [country] until both are done. 3. If a volunteer says they serve with you, may we ring you to confirm it? Their card then says "confirmed with [organisation]" to the stranger they write to. What we promise is on one page, written for exactly this conversation: eververse.org/partners.html. Every guide confirms their identity before their first reply (we pay for the check); a new guide sees only celebrations until a person has read their first three replies; a reply cannot contain a phone number, a link or a request for money; and anyone can report anything in one tap, to a person. Guides are not paid and the person asking never pays. Each guide can print a signed letter of service. If any of the three is possible, reply to this address and a person will answer. If none is, thank you for reading this far. EverVerse Team team@eververse.org · eververse.org/partners.html
A7: English — follow-up (day 10)
A8: FOLLOW-UP (day 10, once) ------------------------ Subject: Re: One of your people, one blessing Dear [name], A short follow-up in case the note below reached a busy inbox. The smallest of the three asks is the one hour on the helpline and the language — it is the thing that lets us open [country] safely. If there is someone we could speak to for that alone, we would be grateful. EverVerse Team
A10: Spanish draft (MX) — native review before sending
A11: EMAIL — Spanish draft (MX). HAVE A NATIVE SPEAKER READ IT BEFORE SENDING. ------------------------------------------------------------------------- Asunto: Una persona de su comunidad, una bendición — una petición de voluntariado de EverVerse Estimados [oficina / nombre]: Esta noche alguien de su tradición va a escribir sobre lo peor que le está pasando — una muerte, una enfermedad, un matrimonio que se rompe, una fe que se ha quedado en silencio — con la esperanza de que una persona real le responda. En eververse.org tenemos el Círculo de Bendiciones: un servicio gratuito donde un adulto escribe de forma anónima y un voluntario verificado de su misma fe le responde una sola vez, con un versículo de su propia escritura y unas palabras honestas suyas. Sin cuenta, sin nada que comprar, y sin que ninguna inteligencia artificial escriba una sola palabra. Queremos abrirlo en México con ustedes. Tres peticiones, de mayor a menor: 1. Diez personas de su comunidad que hayan pasado por algo difícil y puedan escribir una bendición cada una. No hace falta ser clérigo. Diez minutos para aplicar; una persona lee cada solicitud: eververse.org/guides.html 2. Una hora de una persona que viva en México: para confirmar que la línea de crisis que mostramos — SAPTEL, 800 911 2000 — es la correcta, y para leer las frases con las que reconocemos una crisis en español. No promoveremos el Círculo en México hasta que ambas cosas estén hechas. 3. Si un voluntario dice que sirve con ustedes, ¿podemos llamarles para confirmarlo? Lo que prometemos está en una página: eververse.org/partners.html. Los guías no reciben pago y quien escribe nunca paga. Si alguna de las tres es posible, respondan a esta dirección y una persona les contestará. Equipo de EverVerse · team@eververse.org
A13: Portuguese draft (BR) — native review before sending
A14: EMAIL — Portuguese draft (BR). HAVE A NATIVE SPEAKER READ IT BEFORE SENDING. ---------------------------------------------------------------------------- Assunto: Uma pessoa da sua comunidade, uma bênção — um pedido de voluntariado da EverVerse Prezados [secretaria / nome]: Hoje à noite alguém da sua tradição vai escrever sobre a pior coisa da sua vida — uma morte, uma doença, um casamento que acaba, uma fé que silenciou — na esperança de que uma pessoa de verdade responda. Em eververse.org mantemos o Círculo de Bênçãos: um serviço gratuito em que um adulto escreve de forma anônima e um voluntário verificado da sua própria fé responde uma única vez, com um versículo da própria escritura e algumas palavras honestas suas. Sem cadastro, sem nada para comprar, e sem que nenhuma inteligência artificial escreva uma palavra sequer. Queremos abri-lo no Brasil com vocês. Três pedidos, do maior ao menor: 1. Dez pessoas da sua comunidade que já carregaram algo difícil e possam escrever uma bênção cada. Não precisa ser clero. Dez minutos para se candidatar; uma pessoa lê cada candidatura: eververse.org/guides.html 2. Uma hora de uma pessoa que more no Brasil: para confirmar que a linha de crise que mostramos — CVV, 188 — é a correta, e para ler as frases com que reconhecemos uma crise em português. Não divulgaremos o Círculo no Brasil até que as duas coisas estejam feitas. 3. Se um voluntário disser que serve com vocês, podemos ligar para confirmar? O que prometemos está em uma página: eververse.org/partners.html. Os guias não são pagos e quem escreve nunca paga. Se qualquer um dos três for possível, respondam a este endereço e uma pessoa vai responder. Equipe EverVerse · team@eververse.org
A16: Indonesian draft (ID) — native review before sending
A17: EMAIL — Indonesian draft (ID). HAVE A NATIVE SPEAKER READ IT BEFORE SENDING. ---------------------------------------------------------------------------- Subjek: Satu orang dari komunitas Anda, satu berkat — permohonan relawan dari EverVerse Yth. [kantor / nama], Malam ini seseorang dari tradisi Anda akan menulis tentang hal terberat dalam hidupnya — kematian, sakit, pernikahan yang berakhir, iman yang menjadi sunyi — dengan harapan ada orang sungguhan yang membalas. Di eververse.org kami menjalankan Lingkaran Berkat: layanan gratis di mana seorang dewasa menulis tanpa nama, dan seorang relawan terverifikasi dari agamanya sendiri membalas satu kali, dengan satu ayat dari kitab sucinya dan beberapa kata jujur dari dirinya. Tanpa akun, tanpa biaya, dan tidak ada kecerdasan buatan yang menulis satu kata pun. Kami ingin membukanya di Indonesia bersama Anda. Tiga permohonan, dari yang terbesar: 1. Sepuluh orang dari komunitas Anda yang pernah memikul sesuatu yang berat dan bisa menulis satu berkat masing-masing. Tidak harus ulama atau pendeta. Sepuluh menit untuk mendaftar; setiap pendaftaran dibaca oleh manusia: eververse.org/guides.html 2. Satu jam dari satu orang yang tinggal di Indonesia: untuk memastikan layanan krisis yang kami tampilkan — SEJIWA 119 ext. 8 — sudah benar, dan membaca frasa yang kami gunakan untuk mengenali krisis dalam bahasa Indonesia. Kami tidak akan mempromosikan Lingkaran di Indonesia sebelum keduanya selesai. 3. Jika seorang relawan menyebut melayani bersama Anda, bolehkah kami menelepon untuk memastikannya? Apa yang kami janjikan ada di satu halaman: eververse.org/partners.html. Pemandu tidak dibayar, dan orang yang menulis tidak pernah membayar. Jika salah satu dari ketiganya memungkinkan, balas ke alamat ini dan seseorang akan menjawab. Tim EverVerse · team@eververse.org

Sheet Log
A1: Date | B1: CC | C1: Organisation | D1: Ask (G/L/N/C) | E1: Action (sent / follow-up / reply / call) | F1: By | G1: Note (one line, never a reply's contents)
A2: =DATE(2026,9,15) -> 46280 | B2: US | C2: EXAMPLE — Stephen Ministries (delete) | D2: G, C | E2: sent | F2: EverVerse Team | G2: example row — expected format
